# ast2graph エラー処理戦略設計書

## 1. 概要

ast2graphライブラリにおけるエラー処理の統一的な戦略と実装方針を定義します。

## 2. エラー処理の基本方針

### 2.1 原則
- **fail-fast**: 回復不可能なエラーは早期に失敗
- **graceful degradation**: 部分的失敗でも可能な限り処理継続
- **明確なエラー情報**: デバッグ可能な詳細情報を提供
- **ユーザーフレンドリー**: 対処方法を含むエラーメッセージ

### 2.2 エラー分類

| カテゴリ | 処理方針 | 例 |
|---------|---------|---|
| **致命的エラー** | 即座に処理停止 | Neo4j接続不可、メモリ不足 |
| **回復可能エラー** | 再試行後、失敗なら継続 | 一時的なネットワークエラー |
| **警告レベル** | ログ出力して処理継続 | 構文エラーファイル、非推奨機能 |
| **無視可能** | デバッグログのみ | 空ファイル、コメントのみ |

## 3. エラー階層設計

### 3.1 カスタム例外クラス

```python
# 基底例外クラス
class AST2GraphError(Exception):
    """ast2graphライブラリの基底例外クラス"""
    
    def __init__(self, message: str, error_code: str = None, details: dict = None):
        super().__init__(message)
        self.error_code = error_code
        self.details = details or {}
        self.timestamp = datetime.utcnow()

# カテゴリ別例外
class ParseError(AST2GraphError):
    """Python構文解析エラー"""
    pass

class GraphBuildError(AST2GraphError):
    """グラフ構造構築エラー"""
    pass

class Neo4jConnectionError(AST2GraphError):
    """Neo4j接続エラー"""
    pass

class ConfigurationError(AST2GraphError):
    """設定エラー"""
    pass

class ValidationError(AST2GraphError):
    """バリデーションエラー"""
    pass
```

### 3.2 エラーコード体系

```python
class ErrorCode:
    # 構文解析エラー (1xxx)
    SYNTAX_ERROR = "AST_1001"
    ENCODING_ERROR = "AST_1002"
    FILE_NOT_FOUND = "AST_1003"
    
    # グラフ構築エラー (2xxx)
    INVALID_NODE_TYPE = "GRAPH_2001"
    CIRCULAR_DEPENDENCY = "GRAPH_2002"
    
    # Neo4j関連エラー (3xxx)
    CONNECTION_FAILED = "NEO4J_3001"
    AUTHENTICATION_FAILED = "NEO4J_3002"
    QUERY_FAILED = "NEO4J_3003"
    TRANSACTION_FAILED = "NEO4J_3004"
    
    # 設定エラー (4xxx)
    MISSING_CONFIG = "CONFIG_4001"
    INVALID_CONFIG = "CONFIG_4002"
```

## 4. エラー処理実装パターン

### 4.1 ファイル処理のエラーハンドリング

```python
class FileProcessor:
    def __init__(self, error_strategy: str = "continue"):
        """
        error_strategy:
        - "continue": エラーファイルをスキップして継続
        - "fail_fast": 最初のエラーで停止
        - "collect": 全エラーを収集してから報告
        """
        self.error_strategy = error_strategy
        self.errors = []
    
    def process_files(self, file_paths: List[str]) -> ProcessResult:
        results = []
        
        for file_path in file_paths:
            try:
                result = self._process_single_file(file_path)
                results.append(result)
                
            except ParseError as e:
                self._handle_parse_error(e, file_path)
                
            except Exception as e:
                self._handle_unexpected_error(e, file_path)
        
        return ProcessResult(
            successful=results,
            failed=self.errors,
            total=len(file_paths)
        )
    
    def _handle_parse_error(self, error: ParseError, file_path: str):
        error_entry = ErrorEntry(
            file_path=file_path,
            error=error,
            recoverable=True
        )
        
        if self.error_strategy == "fail_fast":
            raise error
        elif self.error_strategy == "continue":
            logger.warning(f"Skipping file {file_path}: {error}")
            self.errors.append(error_entry)
        else:  # collect
            self.errors.append(error_entry)
```

### 4.2 Neo4j接続の再試行戦略

```python
from tenacity import retry, stop_after_attempt, wait_exponential, retry_if_exception_type

class Neo4jConnector:
    def __init__(self, config: dict):
        self.config = config
        self.max_retries = config.get("max_retries", 3)
        self.retry_delay = config.get("retry_delay", 1.0)
    
    @retry(
        stop=stop_after_attempt(3),
        wait=wait_exponential(multiplier=1, min=2, max=10),
        retry=retry_if_exception_type((ServiceUnavailable, SessionExpired))
    )
    def connect(self) -> Driver:
        try:
            driver = GraphDatabase.driver(
                self.config["uri"],
                auth=(self.config["username"], self.config["password"])
            )
            # 接続テスト
            driver.verify_connectivity()
            return driver
            
        except AuthError as e:
            # 認証エラーは再試行しない
            raise Neo4jConnectionError(
                "Authentication failed",
                error_code=ErrorCode.AUTHENTICATION_FAILED,
                details={"uri": self.config["uri"], "username": self.config["username"]}
            ) from e
            
        except ServiceUnavailable as e:
            # サービス利用不可は再試行対象
            logger.warning(f"Neo4j service unavailable, retrying...")
            raise
```

### 4.3 バッチ処理での部分的失敗

```python
class BatchProcessor:
    def __init__(self, neo4j_driver, batch_size: int = 1000):
        self.driver = neo4j_driver
        self.batch_size = batch_size
    
    def process_batch(self, nodes: List[ASTGraphNode]) -> BatchResult:
        successful = []
        failed = []
        
        # バッチを小さなチャンクに分割
        for chunk in self._chunk_nodes(nodes, self.batch_size):
            try:
                self._write_chunk(chunk)
                successful.extend(chunk)
                
            except Neo4jError as e:
                # チャンク失敗時、個別処理にフォールバック
                chunk_failed = self._process_chunk_individually(chunk)
                failed.extend(chunk_failed)
                successful.extend(c for c in chunk if c not in chunk_failed)
        
        return BatchResult(
            successful_count=len(successful),
            failed_count=len(failed),
            failed_nodes=failed,
            partial_success=len(failed) > 0 and len(successful) > 0
        )
    
    def _process_chunk_individually(self, chunk: List[ASTGraphNode]) -> List[ASTGraphNode]:
        """チャンク内の各ノードを個別に処理"""
        failed = []
        
        for node in chunk:
            try:
                self._write_single_node(node)
            except Exception as e:
                logger.error(f"Failed to write node {node.id}: {e}")
                failed.append(node)
        
        return failed
```

## 5. エラー回復メカニズム

### 5.1 自動回復戦略

```python
class ErrorRecovery:
    @staticmethod
    def with_fallback(primary_func, fallback_func, *args, **kwargs):
        """プライマリ関数失敗時にフォールバック実行"""
        try:
            return primary_func(*args, **kwargs)
        except Exception as e:
            logger.warning(f"Primary function failed: {e}, trying fallback")
            return fallback_func(*args, **kwargs)
    
    @staticmethod
    def with_circuit_breaker(func, failure_threshold=5, timeout=60):
        """連続失敗時に一時的に処理を停止"""
        failures = 0
        last_failure_time = None
        
        def wrapper(*args, **kwargs):
            nonlocal failures, last_failure_time
            
            # タイムアウト後はリセット
            if last_failure_time and (time.time() - last_failure_time) > timeout:
                failures = 0
            
            if failures >= failure_threshold:
                raise CircuitBreakerOpen(
                    f"Circuit breaker open after {failures} failures"
                )
            
            try:
                result = func(*args, **kwargs)
                failures = 0  # 成功したらリセット
                return result
            except Exception as e:
                failures += 1
                last_failure_time = time.time()
                raise
        
        return wrapper
```

### 5.2 エラー時の状態保存

```python
class StateRecovery:
    def __init__(self, checkpoint_dir: Path):
        self.checkpoint_dir = checkpoint_dir
        self.checkpoint_dir.mkdir(exist_ok=True)
    
    def save_checkpoint(self, state: ProcessingState):
        """処理状態を保存"""
        checkpoint_file = self.checkpoint_dir / f"checkpoint_{state.timestamp}.json"
        
        with open(checkpoint_file, 'w') as f:
            json.dump({
                "processed_files": state.processed_files,
                "failed_files": state.failed_files,
                "last_successful_file": state.last_successful_file,
                "timestamp": state.timestamp.isoformat()
            }, f)
    
    def resume_from_checkpoint(self) -> Optional[ProcessingState]:
        """最新のチェックポイントから再開"""
        checkpoints = sorted(self.checkpoint_dir.glob("checkpoint_*.json"))
        
        if not checkpoints:
            return None
        
        latest = checkpoints[-1]
        with open(latest) as f:
            data = json.load(f)
            
        return ProcessingState(
            processed_files=set(data["processed_files"]),
            failed_files=data["failed_files"],
            last_successful_file=data["last_successful_file"],
            timestamp=datetime.fromisoformat(data["timestamp"])
        )
```

## 6. エラー報告とログ

### 6.1 構造化エラーレポート

```python
@dataclass
class ErrorReport:
    summary: str
    total_errors: int
    errors_by_type: Dict[str, int]
    errors_by_file: Dict[str, List[Exception]]
    recommendations: List[str]
    
    def to_json(self) -> str:
        return json.dumps({
            "summary": self.summary,
            "total_errors": self.total_errors,
            "errors_by_type": self.errors_by_type,
            "errors_by_file": {
                file: [str(e) for e in errors]
                for file, errors in self.errors_by_file.items()
            },
            "recommendations": self.recommendations,
            "timestamp": datetime.utcnow().isoformat()
        }, indent=2)
    
    def to_markdown(self) -> str:
        md = f"# Error Report\n\n"
        md += f"**Summary**: {self.summary}\n"
        md += f"**Total Errors**: {self.total_errors}\n\n"
        
        md += "## Errors by Type\n"
        for error_type, count in self.errors_by_type.items():
            md += f"- {error_type}: {count}\n"
        
        md += "\n## Recommendations\n"
        for rec in self.recommendations:
            md += f"- {rec}\n"
        
        return md
```

### 6.2 コンテキスト付きログ

```python
class ContextualLogger:
    def __init__(self, logger):
        self.logger = logger
        self.context = {}
    
    def set_context(self, **kwargs):
        self.context.update(kwargs)
    
    def log_error(self, error: Exception, **extra_context):
        context = {**self.context, **extra_context}
        
        self.logger.error(
            f"{error.__class__.__name__}: {str(error)}",
            extra={
                "error_type": error.__class__.__name__,
                "error_code": getattr(error, "error_code", None),
                "file_path": context.get("file_path"),
                "line_number": getattr(error, "lineno", None),
                "traceback": traceback.format_exc(),
                **context
            }
        )
```

## 7. ユーザー向けエラーメッセージ

### 7.1 エラーメッセージテンプレート

```python
ERROR_MESSAGES = {
    ErrorCode.SYNTAX_ERROR: {
        "message": "Python syntax error in file '{file_path}' at line {line_number}",
        "suggestion": "Check the Python syntax. Run 'python -m py_compile {file_path}' to validate.",
        "severity": "warning"
    },
    ErrorCode.CONNECTION_FAILED: {
        "message": "Failed to connect to Neo4j at {uri}",
        "suggestion": "Ensure Neo4j is running and accessible. Check firewall settings for port 7687.",
        "severity": "critical"
    },
    ErrorCode.AUTHENTICATION_FAILED: {
        "message": "Neo4j authentication failed for user '{username}'",
        "suggestion": "Verify NEO4J_PASSWORD environment variable is set correctly.",
        "severity": "critical"
    }
}

def format_user_error(error_code: str, **context) -> str:
    template = ERROR_MESSAGES.get(error_code, {})
    message = template.get("message", "Unknown error").format(**context)
    suggestion = template.get("suggestion", "")
    
    return f"{message}\n💡 {suggestion}" if suggestion else message
```

## 8. エラー処理の設定

### 8.1 グローバル設定

```python
class ErrorHandlingConfig:
    # デフォルト設定
    DEFAULT = {
        "file_error_strategy": "continue",  # continue, fail_fast, collect
        "max_retries": 3,
        "retry_delay": 1.0,
        "enable_checkpoints": True,
        "checkpoint_interval": 100,  # ファイル数
        "detailed_errors": False,  # 本番環境ではFalse推奨
    }
    
    @classmethod
    def from_env(cls):
        """環境変数から設定を読み込み"""
        return {
            "file_error_strategy": os.getenv("AST2GRAPH_ERROR_STRATEGY", "continue"),
            "max_retries": int(os.getenv("AST2GRAPH_MAX_RETRIES", "3")),
            "detailed_errors": os.getenv("AST2GRAPH_DETAILED_ERRORS", "false").lower() == "true",
        }
```

## 9. エラー処理のベストプラクティス

### 9.1 DO
- ✅ 具体的なエラーメッセージと対処法を提供
- ✅ エラーを適切に分類して処理
- ✅ 部分的成功を許容する設計
- ✅ エラー情報を構造化して保存
- ✅ 再実行可能な設計

### 9.2 DON'T
- ❌ 一般的すぎるエラーメッセージ
- ❌ エラーを握りつぶして無視
- ❌ スタックトレースをそのままユーザーに表示
- ❌ リトライなしで即座に失敗
- ❌ エラー時の状態を保存しない

この設計により、ast2graphライブラリは堅牢で使いやすいエラー処理を実現します。